<?xml version='1.0'?>
<robot name="lawnmow" xmlns:xacro="http://www.ros.org/wiki/xacro">
  <xacro:property name="cameraSize" value="0.05"/>
  <xacro:property name="cameraMass" value="0.1"/>
  <xacro:include filename="$(find lawnmow_description)/urdf/lawnmow.gazebo" />
  <xacro:include filename="$(find lawnmow_description)/urdf/materials.xacro" />
  <xacro:include filename="$(find lawnmow_description)/urdf/macros.xacro" />

  <link name='chassis'>

    <pose>0 0 0 0 0 0</pose>

    <inertial>
      <mass value="10.0"/>
      <origin xyz="0 0 .08" rpy=" 0 0 0"/>
      <inertia
          ixx="1.0" ixy="0" ixz="0"
          iyy="1.0" iyz="0"
          izz="1.0"
      />
    </inertial>

    <collision name='collision'>
      <origin xyz="0 0 .08" rpy="0 0 0"/>
      <geometry>
        <mesh scale=".0010 .0010 .0010" filename="package://lawnmow_description/meshes/frame.stl"/>
      </geometry>
    </collision>

    <visual name='chassis_visual'>
      <origin xyz="0 0 .08" rpy=" 0 0 0"/>
      <geometry>
        <mesh scale=".0010 .0010 .0010" filename="package://lawnmow_description/meshes/frame.stl"/>
      </geometry>
      <material name="red">
          <color rgba="1 0 0 1"/>
      </material>
    </visual>
  </link>

  <link name="lfcaster">
    <collision name='lfcollision'>
      <origin xyz="0 0 0" rpy="1.47 0 0"/>
      <geometry>
        <mesh scale=".0010 .0010 .0010" filename="package://lawnmow_description/meshes/caster.stl"/>
      </geometry>

      <surface>
        <friction>
          <ode>
            <mu>0</mu>
            <mu2>0</mu2>
            <slip1>0</slip1>
            <slip2>0</slip2>
          </ode>
        </friction>
      </surface>
    </collision>

    <visual name='lfcaster_visual'>
      <origin xyz="0 0 0" rpy="1.47 0 0"/>
      <geometry>
        <mesh scale=".0010 .0010 .0010" filename="package://lawnmow_description/meshes/caster.stl"/>
      </geometry>
      <material name="black">
          <color rgba="0 0 0 1"/>
      </material>
    </visual>
    <inertial>
      <origin xyz="0.04 0.12 .18" rpy="1.57 0 0"/>
      <mass value="1.5"/>
      <cylinder_inertia m="1.5" r="0.167022" h="0.07"/>
      <inertia
        ixx="1.0" ixy="0.0" ixz="0.0"
        iyy="1.0" iyz="0.0"
        izz="1.0"/>
    </inertial>

  </link>

  <link name="rfcaster">
    <collision name='rfcollision'>
      <origin xyz="0 0 0" rpy="1.47 0 0"/>
      <geometry>
        <mesh scale=".0010 .0010 .0010" filename="package://lawnmow_description/meshes/caster.stl"/>
      </geometry>
      <surface>
        <friction>
          <ode1>
            <mu>0</mu>
            <mu2>0</mu2>
            <slip1>0</slip1>
            <slip2>0</slip2>
          </ode1>
        </friction>
      </surface>
    </collision>

    <visual name='rfcaster_visual'>
      <origin xyz="0 0 0" rpy="1.47 0 0"/>
      <geometry>
        <mesh scale=".0010 .0010 .0010" filename="package://lawnmow_description/meshes/caster.stl"/>
      </geometry>
      <material name="black">
          <color rgba="0 0 0 1"/>
      </material>
    </visual>
    <inertial>
      <origin xyz="0.04 0.12 .18" rpy="1.57 0 0"/>
      <mass value="1.5"/>
      <cylinder_inertia m="1.5" r="0.167022" h="0.07"/>
      <inertia
        ixx="1.0" ixy="0.0" ixz="0.0"
        iyy="1.0" iyz="0.0"
        izz="1.0"/>
    </inertial>

  </link>


  <link name="left_wheel">
    <collision name="collision">
      <origin xyz="0 0 0" rpy="0 0 0"/>
      <geometry>
        <mesh scale=".0010 .0010 .0010" filename="package://lawnmow_description/meshes/wheel.stl"/>
      </geometry>
    </collision>

    <visual name="left_wheel_visual">
      <origin xyz="0 0 0" rpy="0 0 0"/>
      <geometry>
        <mesh scale=".0010 .0010 .0010" filename="package://lawnmow_description/meshes/wheel.stl"/>
      </geometry>
      <material name="black">
          <color rgba="1 0 0 1"/>
      </material>
    </visual>
    
    <inertial>
      <origin xyz="0 0 0" rpy="0 1.57 0"/>
      <mass value="1.5"/>
      <cylinder_inertia m="1.5" r="0.167022" h="0.07"/>
      <inertia
        ixx="1.0" ixy="0.0" ixz="0.0"
        iyy="1.0" iyz="0.0"
        izz="1.0"/>
    </inertial>
  </link>

  <link name="right_wheel">
    <collision name="collision">
      <origin xyz="0 0 0" rpy="0 0 0"/>
      <geometry>
        <mesh scale=".0010 .0010 .0010" filename="package://lawnmow_description/meshes/wheel.stl"/>
      </geometry>
    </collision>

    <visual name="right_wheel_visual">
      <origin xyz="0 0 0" rpy="0 0 0"/>
      <geometry>
        <mesh scale=".0010 .0010 .0010" filename="package://lawnmow_description/meshes/wheel.stl"/>
      </geometry>
      <material name="black">
          <color rgba="1 0 0 1"/>
      </material>
    </visual>

    <inertial>
      <origin xyz="0 0 0" rpy="0 1.57 0"/>
      <mass value="1.5"/>
      <cylinder_inertia m="1.5" r="0.167022" h="0.07"/>
      <inertia
        ixx="1.0" ixy="0.0" ixz="0.0"
        iyy="1.0" iyz="0.0"
        izz="1.0"/>
    </inertial>
  </link>

  <joint type="fixed" name="lfcaster_hinge">
    <origin xyz="-0.208 0.32 0" rpy="-1.57 0 0"/>    
    <child link="lfcaster"/>
    <parent link="chassis"/>
    <axis xyz="0 0 1" rpy="0 0 0"/>
    <limit effort="100" velocity="100"/>
    <joint_properties damping="0.0" friction="0.0"/>
  </joint>

  <joint type="fixed" name="rfcaster_hinge">
    <origin xyz="0.208 0.32 0" rpy="-1.57 0 0"/>
    <child link="rfcaster"/>
    <parent link="chassis"/>
    <axis xyz="0 0 1" rpy="0 0 0"/>
    <limit effort="100" velocity="100"/>
    <joint_properties damping="0.0" friction="0.0"/>
  </joint>


  <joint type="continuous" name="left_wheel_hinge">
    <origin xyz="-0.3 -0.2 0" rpy="0 0 0"/>
    <child link="left_wheel"/>
    <parent link="chassis"/>
    <axis xyz="1 0 0" rpy="0 0 0"/>
    <limit effort="100" velocity="100"/>
    <joint_properties damping="0.0" friction="0.0"/>
  </joint>

  <joint type="continuous" name="right_wheel_hinge">
    <origin xyz="0.3 -0.2 0" rpy="0 0 0"/>
    <child link="right_wheel"/>
    <parent link="chassis"/>
    <axis xyz="1 0 0" rpy="0 0 0"/>
    <limit effort="100" velocity="100"/>
    <joint_properties damping="0.0" friction="0.0"/>
  </joint>


  <link name="camera">
    <collision>
      <origin xyz="0 0 0" rpy="0 0 0"/>
      <geometry>
        <box size="${cameraSize} ${cameraSize} ${cameraSize}"/>
      </geometry>
    </collision>

    <visual>
      <origin xyz="0 .19 0.32" rpy="0 0 0"/>
      <geometry>
        <box size="${cameraSize} ${cameraSize} ${cameraSize}"/>
      </geometry>
      <material name="green"/>
    </visual>

    <inertial>
      <mass value="${cameraMass}" />
      <origin xyz="0 0 0" rpy="0 0 0"/>
      <box_inertia m="${cameraMass}" x="${cameraSize}" y="${cameraSize}" z="${cameraSize}" />
      <inertia ixx="1e-6" ixy="0" ixz="0" iyy="1e-6" iyz="0" izz="1e-6" />
    </inertial>
  </link>

  <joint name="camera_joint" type="fixed">
    <axis xyz="0 1 0" />
    <origin xyz="0 0 0" rpy="0 0 0"/>
    <parent link="chassis"/>
    <child link="camera"/>
  </joint>


</robot>
